Workbook
Name graad: [1]graad!$C$2:$D$5

Sheet semester1
A1: klas: | B1: 1 Balo | D1: Periode: | F1: 42736
A2: Evaluatie Januari 2017
D3: Nederlands | E3: Wiskunde | F3: Frans | G3: Totaal
A4: Nr | B4: Naam | C4: Voornaam | D4: 20 | E4: 20 | F4: 20 | G4: 60
A5: 1 | B5: Alvarez | C5: Joery | D5: 10 | E5: 13 | F5: 14 | G5: =SUM(D5:F5) -> 37
A6: 2 | B6: Bruyneels | C6: Yannick | D6: 18 | E6: 14 | F6: 12 | G6: =SUM(D6:F6) -> 44
A7: 3 | B7: Coppens | C7: Karen | D7: 10 | E7: 6 | F7: 8 | G7: =SUM(D7:F7) -> 24
A8: 4 | B8: Deman | C8: Laurens | D8: 10 | E8: 19 | F8: 12 | G8: =SUM(D8:F8) -> 41
A9: 5 | B9: Dils | C9: Katrien | D9: 4 | E9: 12 | F9: 13 | G9: =SUM(D9:F9) -> 29
A10: 6 | B10: Fransen | C10: Oliver | D10: 5 | E10: 10 | F10: 10 | G10: =SUM(D10:F10) -> 25
A11: 7 | B11: Jansen | C11: Kobe | D11: 12 | E11: 10 | F11: 10 | G11: =SUM(D11:F11) -> 32
A12: 8 | B12: Kanps | C12: Jorien | D12: 9 | E12: 12 | F12: 9 | G12: =SUM(D12:F12) -> 30
A13: 9 | B13: Kenis | C13: Ward | D13: 3 | E13: 12 | F13: 7 | G13: =SUM(D13:F13) -> 22
A14: 10 | B14: Kop | C14: Dimi | D14: 9 | E14: 14 | F14: 12 | G14: =SUM(D14:F14) -> 35
A15: 11 | B15: Maers | C15: Jasper | D15: 6 | E15: 8 | F15: 2 | G15: =SUM(D15:F15) -> 16
A16: 12 | B16: Vandevelde | C16: Carolien | D16: 7 | E16: 5 | F16: 14 | G16: =SUM(D16:F16) -> 26
... A18: 14 | B18: Wilmsen | C18: Kevin | D18: 8 | E18: 6 | F18: 9 | G18: =SUM(D18:F18) -> 23
D19: =AVERAGE(D5:D18) -> 8.5714286 | E19: =AVERAGE(E5:E18) -> 11.071429 | F19: =AVERAGE(F5:F18) -> 10.285714 | G19: =AVERAGE(G5:G18) -> 29.928571 | H19: gemiddelde
D20: =MEDIAN(D5:D18) -> 9 | E20: =MEDIAN(E5:E18) -> 12 | F20: =MEDIAN(F5:F18) -> 11 | G20: =MEDIAN(G5:G18) -> 29.5 | H20: mediaan
A21: aantal studenten: | C21: =COUNTA(B5:B18) -> 14
A22: slechtste resultaat: | C22: =MIN(D5:F18) -> 2
A23: beste resultaat: | C23: =MAX(D5:F18) -> 19

Sheet semester2
A1: klas: | B1: 1 Balo | D1: Periode: | F1: 42736
A2: Evaluatie juni 2017
D3: Nederlands | E3: Wiskunde | F3: Frans | G3: Totaal | H3: Percentage
A4: Nr | B4: Naam | C4: Voornaam | D4: 20 | E4: 20 | F4: 20 | G4: 60
A5: 1 | B5: Alvarez | C5: Joery | D5: 12 | E5: 10 | F5: 13 | G5: =SUM(D5:F5) -> 35 | H5: =G5/60 -> 0.58333333
A6: 2 | B6: Bruyneels | C6: Yannick | D6: 18 | E6: 16 | F6: 15 | G6: =SUM(D6:F6) -> 49 | H6: =G6/60 -> 0.81666667
A7: 3 | B7: Coppens | C7: Karen | D7: 12 | E7: 6 | F7: 10 | G7: =SUM(D7:F7) -> 28 | H7: =G7/60 -> 0.46666667
A8: 4 | B8: Deman | C8: Laurens | D8: 12 | E8: 18 | F8: 13 | G8: =SUM(D8:F8) -> 43 | H8: =G8/60 -> 0.71666667
A9: 5 | B9: Dils | C9: Katrien | D9: 6 | E9: 14 | F9: 8 | G9: =SUM(D9:F9) -> 28 | H9: =G9/60 -> 0.46666667
A10: 6 | B10: Fransen | C10: Oliver | D10: 5 | E10: 13 | F10: 8 | G10: =SUM(D10:F10) -> 26 | H10: =G10/60 -> 0.43333333
A11: 7 | B11: Jansen | C11: Kobe | D11: 12 | E11: 11 | F11: 13 | G11: =SUM(D11:F11) -> 36 | H11: =G11/60 -> 0.6
A12: 8 | B12: Kanps | C12: Jorien | D12: 10 | E12: 13 | F12: 10 | G12: =SUM(D12:F12) -> 33 | H12: =G12/60 -> 0.55
A13: 9 | B13: Kenis | C13: Ward | D13: 4 | E13: 13 | F13: 6 | G13: =SUM(D13:F13) -> 23 | H13: =G13/60 -> 0.38333333
A14: 10 | B14: Kop | C14: Dimi | D14: 15 | E14: 13 | F14: 16 | G14: =SUM(D14:F14) -> 44 | H14: =G14/60 -> 0.73333333
A15: 11 | B15: Maers | C15: Jasper | D15: 5 | E15: 10 | F15: 4 | G15: =SUM(D15:F15) -> 19 | H15: =G15/60 -> 0.31666667
A16: 12 | B16: Vandevelde | C16: Carolien | D16: 5 | E16: 5 | F16: 16 | G16: =SUM(D16:F16) -> 26 | H16: =G16/60 -> 0.43333333
... A18: 14 | B18: Wilmsen | C18: Kevin | D18: 10 | E18: 8 | F18: 10 | G18: =SUM(D18:F18) -> 28 | H18: =G18/60 -> 0.46666667
D19: =AVERAGE(D5:D18) -> 9.5714286 | E19: =AVERAGE(E5:E18) -> 11.785714 | F19: =AVERAGE(F5:F18) -> 11.142857 | G19: =AVERAGE(G5:G18) -> 32.5 | H19: gemiddelde
D20: =MEDIAN(D5:D18) -> 10 | E20: =MEDIAN(E5:E18) -> 13 | F20: =MEDIAN(F5:F18) -> 11.5 | G20: =MEDIAN(G5:G18) -> 30.5 | H20: mediaan
A21: aantal studenten: | C21: =COUNTA(B5:B18) -> 14
A22: slechtste resultaat: | C22: =MIN(D5:F18) -> 4
A23: beste resultaat: | C23: =MAX(D5:F18) -> 18

Sheet totaal
A1: klas: | B1: 1 Balo | D1: Periode: | F1: 42736
A2: Evaluatie totaal
D3: Nederlands | E3: Wiskunde | F3: Frans | G3: Totaal | H3: Percentage | I3: graad
A4: Nr | B4: Naam | C4: Voornaam | D4: 20 | E4: 20 | F4: 20 | G4: 60
A5: 1 | B5: Alvarez | C5: Joery | D5: =semester1!D5*0.4+semester2!D5*0.6 -> 11.2 | E5: =semester1!E5*0.4+semester2!E5*0.6 -> 11.2 | F5: =semester1!F5*0.4+semester2!F5*0.6 -> 13.4 | G5: =SUM(D5:F5) -> 35.8 | H5: =G5/60 -> 0.59666667 | I5: =IF(H5<0.5,"onvoldoende",IF(H5<0.68,"voldoende",IF(H5<0.75,"onderscheiding","grote onderscheiding"))) -> voldoende
A6: 2 | B6: Bruyneels | C6: Yannick | D6: =semester1!D6*0.4+semester2!D6*0.6 -> 18 | E6: =semester1!E6*0.4+semester2!E6*0.6 -> 15.2 | F6: =semester1!F6*0.4+semester2!F6*0.6 -> 13.8 | G6: =SUM(D6:F6) -> 47 | H6: =G6/60 -> 0.78333333 | I6: =IF(H6<0.5,"onvoldoende",IF(H6<0.68,"voldoende",IF(H6<0.75,"onderscheiding","grote onderscheiding"))) -> grote onderscheiding
A7: 3 | B7: Coppens | C7: Karen | D7: =semester1!D7*0.4+semester2!D7*0.6 -> 11.2 | E7: =semester1!E7*0.4+semester2!E7*0.6 -> 6 | F7: =semester1!F7*0.4+semester2!F7*0.6 -> 9.2 | G7: =SUM(D7:F7) -> 26.4 | H7: =G7/60 -> 0.44 | I7: =IF(H7<0.5,"onvoldoende",IF(H7<0.68,"voldoende",IF(H7<0.75,"onderscheiding","grote onderscheiding"))) -> onvoldoende
A8: 4 | B8: Deman | C8: Laurens | D8: =semester1!D8*0.4+semester2!D8*0.6 -> 11.2 | E8: =semester1!E8*0.4+semester2!E8*0.6 -> 18.4 | F8: =semester1!F8*0.4+semester2!F8*0.6 -> 12.6 | G8: =SUM(D8:F8) -> 42.2 | H8: =G8/60 -> 0.70333333 | I8: =IF(H8<0.5,"onvoldoende",IF(H8<0.68,"voldoende",IF(H8<0.75,"onderscheiding","grote onderscheiding"))) -> onderscheiding
A9: 5 | B9: Dils | C9: Katrien | D9: =semester1!D9*0.4+semester2!D9*0.6 -> 5.2 | E9: =semester1!E9*0.4+semester2!E9*0.6 -> 13.2 | F9: =semester1!F9*0.4+semester2!F9*0.6 -> 10 | G9: =SUM(D9:F9) -> 28.4 | H9: =G9/60 -> 0.47333333 | I9: =IF(H9<0.5,"onvoldoende",IF(H9<0.68,"voldoende",IF(H9<0.75,"onderscheiding","grote onderscheiding"))) -> onvoldoende
A10: 6 | B10: Fransen | C10: Oliver | D10: =semester1!D10*0.4+semester2!D10*0.6 -> 5 | E10: =semester1!E10*0.4+semester2!E10*0.6 -> 11.8 | F10: =semester1!F10*0.4+semester2!F10*0.6 -> 8.8 | G10: =SUM(D10:F10) -> 25.6 | H10: =G10/60 -> 0.42666667 | I10: =IF(H10<0.5,"onvoldoende",IF(H10<0.68,"voldoende",IF(H10<0.75,"onderscheiding","grote onderscheiding"))) -> onvoldoende
A11: 7 | B11: Jansen | C11: Kobe | D11: =semester1!D11*0.4+semester2!D11*0.6 -> 12 | E11: =semester1!E11*0.4+semester2!E11*0.6 -> 10.6 | F11: =semester1!F11*0.4+semester2!F11*0.6 -> 11.8 | G11: =SUM(D11:F11) -> 34.4 | H11: =G11/60 -> 0.57333333 | I11: =IF(H11<0.5,"onvoldoende",IF(H11<0.68,"voldoende",IF(H11<0.75,"onderscheiding","grote onderscheiding"))) -> voldoende
A12: 8 | B12: Kanps | C12: Jorien | D12: =semester1!D12*0.4+semester2!D12*0.6 -> 9.6 | E12: =semester1!E12*0.4+semester2!E12*0.6 -> 12.6 | F12: =semester1!F12*0.4+semester2!F12*0.6 -> 9.6 | G12: =SUM(D12:F12) -> 31.8 | H12: =G12/60 -> 0.53 | I12: =IF(H12<0.5,"onvoldoende",IF(H12<0.68,"voldoende",IF(H12<0.75,"onderscheiding","grote onderscheiding"))) -> voldoende
A13: 9 | B13: Kenis | C13: Ward | D13: =semester1!D13*0.4+semester2!D13*0.6 -> 3.6 | E13: =semester1!E13*0.4+semester2!E13*0.6 -> 12.6 | F13: =semester1!F13*0.4+semester2!F13*0.6 -> 6.4 | G13: =SUM(D13:F13) -> 22.6 | H13: =G13/60 -> 0.37666667 | I13: =IF(H13<0.5,"onvoldoende",IF(H13<0.68,"voldoende",IF(H13<0.75,"onderscheiding","grote onderscheiding"))) -> onvoldoende
A14: 10 | B14: Kop | C14: Dimi | D14: =semester1!D14*0.4+semester2!D14*0.6 -> 12.6 | E14: =semester1!E14*0.4+semester2!E14*0.6 -> 13.4 | F14: =semester1!F14*0.4+semester2!F14*0.6 -> 14.4 | G14: =SUM(D14:F14) -> 40.4 | H14: =G14/60 -> 0.67333333 | I14: =IF(H14<0.5,"onvoldoende",IF(H14<0.68,"voldoende",IF(H14<0.75,"onderscheiding","grote onderscheiding"))) -> voldoende
A15: 11 | B15: Maers | C15: Jasper | D15: =semester1!D15*0.4+semester2!D15*0.6 -> 5.4 | E15: =semester1!E15*0.4+semester2!E15*0.6 -> 9.2 | F15: =semester1!F15*0.4+semester2!F15*0.6 -> 3.2 | G15: =SUM(D15:F15) -> 17.8 | H15: =G15/60 -> 0.29666667 | I15: =IF(H15<0.5,"onvoldoende",IF(H15<0.68,"voldoende",IF(H15<0.75,"onderscheiding","grote onderscheiding"))) -> onvoldoende
A16: 12 | B16: Vandevelde | C16: Carolien | D16: =semester1!D16*0.4+semester2!D16*0.6 -> 5.8 | E16: =semester1!E16*0.4+semester2!E16*0.6 -> 5 | F16: =semester1!F16*0.4+semester2!F16*0.6 -> 15.2 | G16: =SUM(D16:F16) -> 26 | H16: =G16/60 -> 0.43333333 | I16: =IF(H16<0.5,"onvoldoende",IF(H16<0.68,"voldoende",IF(H16<0.75,"onderscheiding","grote onderscheiding"))) -> onvoldoende
... A18: 14 | B18: Wilmsen | C18: Kevin | D18: =semester1!D18*0.4+semester2!D18*0.6 -> 9.2 | E18: =semester1!E18*0.4+semester2!E18*0.6 -> 7.2 | F18: =semester1!F18*0.4+semester2!F18*0.6 -> 9.6 | G18: =SUM(D18:F18) -> 26 | H18: =G18/60 -> 0.43333333 | I18: =IF(H18<0.5,"onvoldoende",IF(H18<0.68,"voldoende",IF(H18<0.75,"onderscheiding","grote onderscheiding"))) -> onvoldoende
D19: =AVERAGE(D5:D18) -> 9.1714286 | E19: =AVERAGE(E5:E18) -> 11.5 | F19: =AVERAGE(F5:F18) -> 10.8 | G19: =AVERAGE(G5:G18) -> 31.471429 | H19: gemiddelde
D20: =MEDIAN(D5:D18) -> 9.4 | E20: =MEDIAN(E5:E18) -> 12.2 | F20: =MEDIAN(F5:F18) -> 10.9 | G20: =MEDIAN(G5:G18) -> 30.1 | H20: mediaan
A21: aantal studenten: | C21: =COUNTA(B5:B18) -> 14
A22: slechtste resultaat: | C22: =MIN(D5:F18) -> 3.2
A23: beste resultaat: | C23: =MAX(D5:F18) -> 18.4

Sheet Blad4
B2: % | C2: graad
B3: 0 | C3: onvoldoende
B4: 0.5 | C4: voldoende
B5: 0.68 | C5: onderscheiding
B6: 0.75 | C6: grote onderscheiding

Sheet Blad2
A1: Alvarez | B1: Joery | C1: 12 | D1: 10 | E1: 13
A2: Bruynseels | B2: Yannick | C2: 18 | D2: 16 | E2: 15
A3: Coppens | B3: Karen | C3: 12 | D3: 6 | E3: 10
A4: Deman | B4: Laurens | C4: 12 | D4: 18 | E4: 13
A5: Dils | B5: Katrien | C5: 6 | D5: 14 | E5: 8
A6: Fransen | B6: Oliver | C6: 5 | D6: 13 | E6: 8
A7: Jansen | B7: Kobe | C7: 12 | D7: 11 | E7: 13
A8: Kanps | B8: Jorien | C8: 10 | D8: 13 | E8: 10
A9: Kenis | B9: Ward | C9: 4 | D9: 13 | E9: 6
A10: Kop | B10: Dimi | C10: 15 | D10: 13 | E10: 16
A11: Maers | B11: Jasper | C11: 5 | D11: 10 | E11: 4
A12: Vandevelde | B12: Carolien | C12: 5 | D12: 5 | E12: 16
... A14: Wilmsen | B14: Kevin | C14: 10 | D14: 8 | E14: 10

Sheet filter1
A1: Kltnr | B1: Klantnaam | C1: Straat | D1: Postcode | E1: Woonplaats | F1: Telefoonnummer | G1: Faxnummer | H1: Aard
A2: 15 | B2: Cuypers Anny | C2: Rauwelkoven 151 | D2: 2440 | E2: GEEL | F2: (014)59 00 84 | H2: 1
A3: 3 | B3: De Brabander Jean | C3: Markt 5 | D3: 2440 | E3: GEEL | H3: 0
A4: 10 | B4: De Prater Jules | C4: Kievit 3 | D4: 2400 | E4: MOL | H4: 0
A5: 12 | B5: De Vries Anna | C5: Vreesstraat 2 | D5: 2400 | E5: MOL | H5: 1
A6: 11 | B6: De Waele Erna | C6: Locomotiefstraat | D6: 2440 | E6: GEEL | F6: (014)12 13 14 | G6: (014)12 14 15 | H6: 1
A7: 18 | B7: Dils Lieve | C7: Grote Meur 48 | D7: 3201 | E7: LANGDORP | F7: (016)56 11 61 | H7: 1
A8: 19 | B8: Geeraerts Christa | C8: Kleine Weg 8 | D8: 3582 | E8: BERINGEN | F8: (011)53 38 02 | H8: 1
A9: 17 | B9: Haest Martine | C9: St.Theresiastraat 127 | D9: 2400 | E9: MOL | F9: (014)32 00 35 | H9: 1
A10: 16 | B10: Ruts Nadine | C10: Esdreef 162 | D10: 2400 | E10: MOL | F10: (014)32 28 15 | H10: 1
A11: 8 | B11: Smeyers Gustaaf | C11: In 't Eegdeken 12 | D11: 2440 | E11: GEEL | F11: (014)58 96 32 | H11: 0
A12: 9 | B12: Sterckx Jos | C12: In 't Eegdeken 13 | D12: 2440 | E12: GEEL | F12: (014)58 96 33 | H12: 0
A13: 4 | B13: Stevens Louis | C13: Zwartwaterweg 34 | D13: 9000 | E13: GENT | F13: (09 )123 65 47 | H13: 0
A14: 6 | B14: Van Hout Linda | C14: Spoorwegstraat 19 | D14: 2490 | E14: BALEN | F14: (014)31 32 32 | H14: 1
A15: 7 | B15: Van Hout Linda | C15: Demaretak 1 | D15: 2440 | E15: GEEL | H15: 1
A16: 5 | B16: Van Meensel An | C16: Gerheide 51 | D16: 2440 | E16: GEEL | H16: 1
A17: 14 | B17: Vandoninck Greet | C17: Belgiëlei 3 | D17: 2260 | E17: WESTERLO | F17: (014)54 66 88 | H17: 1
A18: 1 | B18: Vervoort Jos | C18: Nieuwstraat 31 | D18: 2440 | E18: GEEL | F18: (014)58 58 58 | H18: 0
A19: 13 | B19: Vos José | C19: Vesderstraat 5 | D19: 2440 | E19: GEEL | F19: (014)88 99 77 | H19: 1
A20: 2 | B20: Wilmaers Louisa | C20: Leuvensestwg 1 | D20: 1000 | E20: BRUSSEL | F20: ( 02)123 54 68 | G20: ( 02)123 54 69 | H20: 1

Sheet filter2
A1: Stagestudenten BM Turnhout
A2: Nummer | B2: Gebruikersnummer | C2: Voornaam | D2: Naam | E2: Optie | F2: Extra info | G2: e-mail
A3: 189025 | B3: s0189025 | C3: Sanne | D3: Wouters | E3: RP | G3: sanne.wouters@stu.khk.be
A4: 196442 | B4: s0196442 | C4: Sabrina | D4: Meeuwssen | E4: RP | G4: sabrina.meeuwssen@stu.khk.be
A5: 230866 | B5: r0230866 | C5: Sander | D5: Verstraelen | E5: AF | F5: stage in buitenland | G5: sander.verstraelen1@stu.khk.be
A6: 237197 | B6: r0237197 | C6: Annick | D6: Bax | E6: RP | G6: annick.bax@stu.khk.be
A7: 240778 | B7: r0240778 | C7: Yannick | D7: Stoffelen | E7: FV | F7: stage in buitenland | G7: yannick.stoffelen@stu.khk.be
A8: 241146 | B8: r0241146 | C8: Tinne | D8: Miechielsen | E8: FV | G8: tine.miechielsen@stu.khk.be
A9: 243447 | B9: r0243447 | C9: Caroline | D9: Verheyen | E9: AF | G9: caroline.verheyen@stu.khk.be
A10: 245184 | B10: r0245184 | C10: Carl | D10: François | E10: MA | G10: carl.francois@stu.khk.be
A11: 245418 | B11: r0245418 | C11: Nick | D11: Balemans | E11: AF | G11: nick.balemans@stu.khk.be
A12: 245447 | B12: r0245447 | C12: Tom | D12: Van Vugt | E12: FV | G12: tom.van.vugt@stu.khk.be
A13: 246030 | B13: r0246030 | C13: Jonah | D13: Hendrickx | E13: FV | G13: jonah.hendrickx@stu.khk.be
A14: 246675 | B14: r0246675 | C14: Gitte | D14: Govaerts | E14: RP | G14: gitte.govaerts@stu.khk.be
A15: 247100 | B15: r0247100 | C15: Barbara | D15: Hapers | E15: MA | G15: barbara.hapers@stu.khk.be
A16: 247301 | B16: r0247301 | C16: Katrien | D16: Van Hoek | E16: MA | F16: stage in buitenland | G16: katrien.van.hoek@stu.khk.be
A17: 247499 | B17: r0247499 | C17: Dimi | D17: Van Loon | E17: AF | G17: dimi.van.loon@stu.khk.be
A18: 247509 | B18: r0247509 | C18: Nick | D18: Brijs | E18: AF | G18: nick.brijs@stu.khk.be
A19: 247529 | B19: r0247529 | C19: Katrien | D19: Hautera | E19: AF | F19: 40909 | G19: katrien.hautera@stu.khk.be
A20: 247616 | B20: r0247616 | C20: Caroline | D20: Vreys | E20: FV | G20: caroline.vreys@stu.khk.be
A21: 247925 | B21: r0247925 | C21: Kevin | D21: Linden | E21: MA | G21: kevin.linden@stu.khk.be
A22: 247952 | B22: r0247952 | C22: Jeroen | D22: Verdick | E22: AF | F22: stage in buitenland | G22: jeroen.verdick@stu.khk.be
A23: 248014 | B23: r0248014 | C23: Tanne | D23: Vanderkaa | E23: MA | G23: tanne.vanderkaa@stu.khk.be
A24: 248188 | B24: r0248188 | C24: Thomas | D24: Diels | E24: MA | G24: thomas.diels@stu.khk.be
A25: 248965 | B25: r0248965 | C25: Jan | D25: Valenberghs | E25: AF | G25: jan.valenberghs@stu.khk.be
A26: 248981 | B26: r0248981 | C26: Sofie | D26: Fens | E26: AF | G26: sofie.fens@stu.khk.be
A27: 249000 | B27: r0249000 | C27: Lennie | D27: Oorts | E27: AF | G27: lennie.oorts@stu.khk.be
A28: 249246 | B28: r0249246 | C28: Kelly | D28: Swannet | E28: AF | G28: kelly.swannet@stu.khk.be
A29: 249332 | B29: r0249332 | C29: Jordy | D29: Raeymaekers | E29: FV | G29: jordy.raeymaekers@stu.khk.be
A30: 249336 | B30: r0249336 | C30: Kristof | D30: Jacobs | E30: FV | G30: kristof.jacobs@stu.khk.be
A31: 249368 | B31: r0249368 | C31: Stéphanie | D31: Marcus | E31: AF | G31: stephanie.marcus@stu.khk.be
A32: 249508 | B32: r0249508 | C32: Erik | D32: Corluy | E32: FV | G32: erik.corluy@stu.khk.be
A33: 249535 | B33: r0249535 | C33: Stéphanie | D33: Sels | E33: FV | G33: stephanie.sels@stu.khk.be
A34: 249538 | B34: r0249538 | C34: Michiel | D34: Verheyen | E34: AF | G34: michiel.verheyen@stu.khk.be
... A37: 249631 | B37: r0249631 | C37: Maarten | D37: Hoyberghs | E37: MA | G37: maarten.hoyberghs@stu.khk.be
A38: 249646 | B38: r0249646 | C38: Glenn | D38: Bertels | E38: AF | F38: stage in buitenland | G38: glenn.bertels1@stu.khk.be
A39: 249737 | B39: r0249737 | C39: Jolien | D39: Schryvers | E39: AF | G39: jolien.schryvers@stu.khk.be
A40: 249763 | B40: r0249763 | C40: Yannick | D40: Moelans | E40: FV | G40: yannick.moelans@stu.khk.be
A41: 250000 | B41: r0250000 | C41: Joke | D41: Dockx | E41: AF | G41: joke.dockx@stu.khk.be
A42: 250131 | B42: r0250131 | C42: Lore | D42: Janssen | E42: AF | G42: lore.janssen@stu.khk.be
...
